Workbook

Sheet Summary
A1: AI Agent Cost Estimate: AtliQ Lead Capture & Follow-up Assistant
A2: LLM cost only: what the prototype as built spends on AI per conversation and per month (capture on Claude Haiku 5.5, email drafts on Claude Haiku 5.5, Ask AI RAG on Groq), compared across 4 capture models. Hosting and one-time costs excluded.
A4: Headline
A5: Capture model | B5: =Inputs!$B$29 -> Claude Haiku 5.5 (Anthropic)
A6: Monthly task volume | B6: =Inputs!$B$9 -> 2200
A7: LLM calls per task | B7: =Inputs!$B$16 -> 3
A8: Tokens per task (input / output) | B8: =TEXT('Agent Loop'!$B$9,"#,##0")&" / "&TEXT('Agent Loop'!$B$12,"#,##0") -> 4,464 / 1,535
A9: All-in cost per task | B9: ='Agent Loop'!$B$41 -> 0.001735877
A10: Break-even cost per task | B10: ='Cost Saving'!$B$25 -> 1.3257576
A11: Monthly cost of human agents today | B11: ='Cost Saving'!$B$9 -> 4166.6667
A12: Monthly cost with the AI agent (incl. on-demand) | B12: ='Cost Saving'!$B$17 -> 1254.3278
A13: Monthly saving | B13: ='Cost Saving'!$B$20 -> 2912.3388
A14: % saving | B14: ='Cost Saving'!$B$21 -> 0.69896132
A15: Automation rate assumed | B15: =Inputs!$B$51 -> 0.7
A16: One-time costs | B16: ='Cost Saving'!$B$23 -> 0
A17: Payback period (months) | B17: ='Cost Saving'!$B$24 -> 0
A18: of which on-demand (email drafts + questions) | B18: ='Agent Loop'!$B$50 -> 0.5089018
A19: Model comparison (monthly)
A20: Model | B20: Run cost (capture on this model; drafts and Ask AI on their own models) | C20: Total with agent | D20: Monthly saving | E20: % saving
A21: =Inputs!$A$25 -> openai/gpt-oss-120b (Groq) | B21: =('Agent Loop'!$E$31+'Agent Loop'!$B$39+'Agent Loop'!$B$40)*Inputs!$B$9+'Agent Loop'!$B$50+'Cost Saving'!$B$13 -> 4.3581538 | C21: =Summary!$B$21+'Cost Saving'!$B$15+'Cost Saving'!$B$16 -> 1254.3582 | D21: ='Cost Saving'!$B$9-Summary!$C$21 -> 2912.3085 | E21: =IF('Cost Saving'!$B$9=0,0,Summary!$D$21/'Cost Saving'!$B$9) -> 0.69895404 | F21: =IF(Inputs!$A$25=Inputs!$B$29,"Selected","")
A22: =Inputs!$A$26 -> openai/gpt-oss-20b (Groq) | B22: =('Agent Loop'!$E$32+'Agent Loop'!$B$39+'Agent Loop'!$B$40)*Inputs!$B$9+'Agent Loop'!$B$50+'Cost Saving'!$B$13 -> 2.4335278 | C22: =Summary!$B$22+'Cost Saving'!$B$15+'Cost Saving'!$B$16 -> 1252.4335 | D22: ='Cost Saving'!$B$9-Summary!$C$22 -> 2914.2331 | E22: =IF('Cost Saving'!$B$9=0,0,Summary!$D$22/'Cost Saving'!$B$9) -> 0.69941595 | F22: =IF(Inputs!$A$26=Inputs!$B$29,"Selected","")
A23: =Inputs!$A$27 -> qwen/qwen3.8-27b (Groq, preview) | B23: =('Agent Loop'!$E$33+'Agent Loop'!$B$39+'Agent Loop'!$B$40)*Inputs!$B$9+'Agent Loop'!$B$50+'Cost Saving'!$B$13 -> 24.010006 | C23: =Summary!$B$23+'Cost Saving'!$B$15+'Cost Saving'!$B$16 -> 1274.01 | D23: ='Cost Saving'!$B$9-Summary!$C$23 -> 2892.6567 | E23: =IF('Cost Saving'!$B$9=0,0,Summary!$D$23/'Cost Saving'!$B$9) -> 0.6942376 | F23: =IF(Inputs!$A$27=Inputs!$B$29,"Selected","")
A24: =Inputs!$A$28 -> Claude Haiku 5.5 (Anthropic) | B24: =('Agent Loop'!$E$34+'Agent Loop'!$B$39+'Agent Loop'!$B$40)*Inputs!$B$9+'Agent Loop'!$B$50+'Cost Saving'!$B$13 -> 4.3278312 | C24: =Summary!$B$24+'Cost Saving'!$B$15+'Cost Saving'!$B$16 -> 1254.3278 | D24: ='Cost Saving'!$B$9-Summary!$C$24 -> 2912.3388 | E24: =IF('Cost Saving'!$B$9=0,0,Summary!$D$24/'Cost Saving'!$B$9) -> 0.69896132 | F24: =IF(Inputs!$A$28=Inputs!$B$29,"Selected","") -> Selected
A26: Sensitivity: monthly saving by automation rate (selected model)
A27: Automation rate | B27: Monthly saving | C27: % saving
A28: 0.4 | B28: ='Cost Saving'!$B$9*Summary!$A$28-'Agent Loop'!$B$42-'Cost Saving'!$B$13-'Cost Saving'!$B$15 -> 1662.3388 | C28: =IF('Cost Saving'!$B$9=0,0,Summary!$B$28/'Cost Saving'!$B$9) -> 0.39896132
A29: 0.5 | B29: ='Cost Saving'!$B$9*Summary!$A$29-'Agent Loop'!$B$42-'Cost Saving'!$B$13-'Cost Saving'!$B$15 -> 2079.0055 | C29: =IF('Cost Saving'!$B$9=0,0,Summary!$B$29/'Cost Saving'!$B$9) -> 0.49896132
A30: 0.6 | B30: ='Cost Saving'!$B$9*Summary!$A$30-'Agent Loop'!$B$42-'Cost Saving'!$B$13-'Cost Saving'!$B$15 -> 2495.6722 | C30: =IF('Cost Saving'!$B$9=0,0,Summary!$B$30/'Cost Saving'!$B$9) -> 0.59896132
A31: 0.7 | B31: ='Cost Saving'!$B$9*Summary!$A$31-'Agent Loop'!$B$42-'Cost Saving'!$B$13-'Cost Saving'!$B$15 -> 2912.3388 | C31: =IF('Cost Saving'!$B$9=0,0,Summary!$B$31/'Cost Saving'!$B$9) -> 0.69896132
A32: 0.8 | B32: ='Cost Saving'!$B$9*Summary!$A$32-'Agent Loop'!$B$42-'Cost Saving'!$B$13-'Cost Saving'!$B$15 -> 3329.0055 | C32: =IF('Cost Saving'!$B$9=0,0,Summary!$B$32/'Cost Saving'!$B$9) -> 0.79896132
A33: 0.9 | B33: ='Cost Saving'!$B$9*Summary!$A$33-'Agent Loop'!$B$42-'Cost Saving'!$B$13-'Cost Saving'!$B$15 -> 3745.6722 | C33: =IF('Cost Saving'!$B$9=0,0,Summary!$B$33/'Cost Saving'!$B$9) -> 0.89896132
A35: Ask AI (RAG): pipeline questions
A36: Ask AI model | B36: =Inputs!$B$63 -> openai/gpt-oss-120b (Groq)
A37: Retrieval | B37: =IF(Inputs!$B$74=1,"Vector top-"&Inputs!$B$75&" + keyword","Full pipeline snapshot + keyword match (as built)") -> Full pipeline snapshot + keyword match (as built)
A38: Input / output tokens per question | B38: =TEXT('Ask AI (RAG)'!$B$11,"#,##0")&" / "&TEXT('Ask AI (RAG)'!$B$12,"#,##0") -> 3,260 / 600
A39: Cost per question | B39: =INDEX('Ask AI (RAG)'!$D$17:$D$20,MATCH(Inputs!$B$63,'Ask AI (RAG)'!$A$17:$A$20,0)) -> 0.0009339
A40: Monthly Ask AI cost | B40: ='Ask AI (RAG)'!$B$22 -> 0.308187
A41: Monthly embeddings | B41: ='Cost Saving'!$B$13 -> 0
A42: Monthly Ask AI cost at 500 deals: full snapshot | B42: ='Ask AI (RAG)'!$C$37 -> 1.53549
A43: Monthly Ask AI cost at 500 deals: vector top-N | B43: ='Ask AI (RAG)'!$E$37 -> 0.277871

Sheet Inputs
A1: Inputs: AtliQ Lead Capture & Follow-up Assistant
A2: Yellow cells are inputs. Change them and every sheet recalculates.
A4: Input (edit me) | B4: Calculated | C4: Headline result
A6: Task volume
A7: Tasks (conversations / requests) per day | B7: 100
A8: Days per month | B8: 22
A9: Monthly task volume | B9: =Inputs!$B$7*Inputs!$B$8 -> 2200
A11: Agent loop (tokens)
A12: System prompt | B12: 690
A13: Tool definitions / output schema (per call) | B13: 278 | C13: Strict JSON schema sent with every LLM call
A14: User request (the conversation, sent to each call) | B14: 520
A15: Retrieved context per task (RAG) | B15: 0 | C15: 0 if the agent has no knowledge base
A16: LLM calls per task (loop steps) | B16: 3 | C16: Classify + extract + date check (cross-sell folded into the averages)
A17: Output tokens per intermediate call | B17: 178 | C17: Classify ~105 and date check ~250, incl. reasoning
A18: Tool result tokens per step | B18: 0 | C18: 0: pipeline calls are independent, nothing is fed back
A19: Final call output tokens | B19: 1179 | C19: Extraction ~1,105 + cross-sell 25% x 300
A20: Retry / failed-call rate | B20: 0.1 | C20: Extra LLM spend from retries and re-plans
A21: Prompt-cache hit share on static prefix | B21: 0 | C21: 0% if the provider or setup has no prompt caching
A23: LLM models (price per 1M tokens)
A24: Model | B24: Input ($) | C24: Cached input ($) | D24: Output ($) | E24: Tokenizer factor
A25: openai/gpt-oss-120b (Groq) | B25: 0.15 | C25: 0.075 | D25: 0.6 | E25: 1
A26: openai/gpt-oss-20b (Groq) | B26: 0.075 | C26: 0.0375 | D26: 0.3 | E26: 1
A27: qwen/qwen3.8-27b (Groq, preview) | B27: 0.8 | C27: 0.8 | D27: 4 | E27: 1
A28: Claude Haiku 5.5 (Anthropic) | B28: 0.1 | C28: 0.01 | D28: 0.5 | E28: 1.3 | F28: Haiku 5.5 counts the same text as ~30% more tokens
A29: Capture model (classify, extract, dates, cross-sell) | B29: Claude Haiku 5.5 (Anthropic) | C29: Live: LLM_PROVIDER=anthropic, CAPTURE_CLAUDE_EFFORT=low
A31: Guardrail / evaluator calls (per task)
A32: Guardrail model | B32: openai/gpt-oss-120b (Groq) | C32: Usually a small, cheap model
A33: Guardrail calls per task | B33: 0
A34: Input tokens per guardrail call | B34: 0
A35: Output tokens per guardrail call | B35: 0
A37: Paid tools / APIs (per task, $)
A38: Tool | B38: Cost per call | C38: Calls per task
A39: CRM matching, grounding check, masking, reminder rules (deterministic code, no LLM) | B39: 0 | C39: 1
A41: Infrastructure (monthly, $)
A42: Hosting (excluded: LLM cost only) | B42: 0 | C42: Excluded by request
A44: One-time costs ($)
A45: None (LLM cost only) | B45: 0 | C45: Development and go-live excluded by request
A47: Human baseline
A48: Tasks handled per human agent per day | B48: 96 | C48: Manual CRM entry ~5 min per conversation (96 per 8-hour day); $4,000/month blended cost of the four sellers' time (user's figure)
A49: Salary per agent per month ($) | B49: 4000
...

Sheet Agent Loop
A1: Agent Loop
A2: Each conversation runs 3 independent LLM calls on the capture model; on-demand features run on their own models (Inputs rows 62-63)
A4: Tokens per task
A5: Static prefix per call (system prompt + tools) | B5: =Inputs!$B$12+Inputs!$B$13 -> 968
A6: Fixed context per call (user request + RAG context) | B6: =Inputs!$B$14+Inputs!$B$15 -> 520
A7: History fed back per step (tool / earlier results) | B7: =Inputs!$B$18 -> 0
A8: LLM calls per task | B8: =Inputs!$B$16 -> 3
A9: Total input tokens per task | B9: =Inputs!$B$16*('Agent Loop'!$B$5+'Agent Loop'!$B$6)+'Agent Loop'!$B$7*Inputs!$B$16*(Inputs!$B$16-1)/2 -> 4464 | C9: N x (prefix + fixed) + growth x N x (N-1) / 2
A10: of which served from prompt cache | B10: =Inputs!$B$16*'Agent Loop'!$B$5*Inputs!$B$21 -> 0
A11: of which billed at full input price | B11: ='Agent Loop'!$B$9-'Agent Loop'!$B$10 -> 4464
A12: Total output tokens per task | B12: =(Inputs!$B$16-1)*Inputs!$B$17+Inputs!$B$19 -> 1535
A13: Retry / failed-call rate | B13: =Inputs!$B$20 -> 0.1
A15: Step-by-step view (illustrative; totals above use the closed formula)
A16: Step | B16: Input tokens | C16: Output tokens | D16: Running total input
A17: 1 | B17: =IF('Agent Loop'!$A$17<=Inputs!$B$16,'Agent Loop'!$B$5+'Agent Loop'!$B$6+('Agent Loop'!$A$17-1)*'Agent Loop'!$B$7,"") -> 1488 | C17: =IF('Agent Loop'!$A$17<Inputs!$B$16,Inputs!$B$17,IF('Agent Loop'!$A$17=Inputs!$B$16,Inputs!$B$19,"")) -> 178 | D17: =IF(B17="","",SUM($B$17:B17)) -> 1488
A18: 2 | B18: =IF('Agent Loop'!$A$18<=Inputs!$B$16,'Agent Loop'!$B$5+'Agent Loop'!$B$6+('Agent Loop'!$A$18-1)*'Agent Loop'!$B$7,"") -> 1488 | C18: =IF('Agent Loop'!$A$18<Inputs!$B$16,Inputs!$B$17,IF('Agent Loop'!$A$18=Inputs!$B$16,Inputs!$B$19,"")) -> 178 | D18: =IF(B18="","",SUM($B$17:B18)) -> 2976
A19: 3 | B19: =IF('Agent Loop'!$A$19<=Inputs!$B$16,'Agent Loop'!$B$5+'Agent Loop'!$B$6+('Agent Loop'!$A$19-1)*'Agent Loop'!$B$7,"") -> 1488 | C19: =IF('Agent Loop'!$A$19<Inputs!$B$16,Inputs!$B$17,IF('Agent Loop'!$A$19=Inputs!$B$16,Inputs!$B$19,"")) -> 1179 | D19: =IF(B19="","",SUM($B$17:B19)) -> 4464
A20: 4 | B20: =IF('Agent Loop'!$A$20<=Inputs!$B$16,'Agent Loop'!$B$5+'Agent Loop'!$B$6+('Agent Loop'!$A$20-1)*'Agent Loop'!$B$7,"") | C20: =IF('Agent Loop'!$A$20<Inputs!$B$16,Inputs!$B$17,IF('Agent Loop'!$A$20=Inputs!$B$16,Inputs!$B$19,"")) | D20: =IF(B20="","",SUM($B$17:B20))
A21: 5 | B21: =IF('Agent Loop'!$A$21<=Inputs!$B$16,'Agent Loop'!$B$5+'Agent Loop'!$B$6+('Agent Loop'!$A$21-1)*'Agent Loop'!$B$7,"") | C21: =IF('Agent Loop'!$A$21<Inputs!$B$16,Inputs!$B$17,IF('Agent Loop'!$A$21=Inputs!$B$16,Inputs!$B$19,"")) | D21: =IF(B21="","",SUM($B$17:B21))
A22: 6 | B22: =IF('Agent Loop'!$A$22<=Inputs!$B$16,'Agent Loop'!$B$5+'Agent Loop'!$B$6+('Agent Loop'!$A$22-1)*'Agent Loop'!$B$7,"") | C22: =IF('Agent Loop'!$A$22<Inputs!$B$16,Inputs!$B$17,IF('Agent Loop'!$A$22=Inputs!$B$16,Inputs!$B$19,"")) | D22: =IF(B22="","",SUM($B$17:B22))
A23: 7 | B23: =IF('Agent Loop'!$A$23<=Inputs!$B$16,'Agent Loop'!$B$5+'Agent Loop'!$B$6+('Agent Loop'!$A$23-1)*'Agent Loop'!$B$7,"") | C23: =IF('Agent Loop'!$A$23<Inputs!$B$16,Inputs!$B$17,IF('Agent Loop'!$A$23=Inputs!$B$16,Inputs!$B$19,"")) | D23: =IF(B23="","",SUM($B$17:B23))
A24: 8 | B24: =IF('Agent Loop'!$A$24<=Inputs!$B$16,'Agent Loop'!$B$5+'Agent Loop'!$B$6+('Agent Loop'!$A$24-1)*'Agent Loop'!$B$7,"") | C24: =IF('Agent Loop'!$A$24<Inputs!$B$16,Inputs!$B$17,IF('Agent Loop'!$A$24=Inputs!$B$16,Inputs!$B$19,"")) | D24: =IF(B24="","",SUM($B$17:B24))
A25: 9 | B25: =IF('Agent Loop'!$A$25<=Inputs!$B$16,'Agent Loop'!$B$5+'Agent Loop'!$B$6+('Agent Loop'!$A$25-1)*'Agent Loop'!$B$7,"") | C25: =IF('Agent Loop'!$A$25<Inputs!$B$16,Inputs!$B$17,IF('Agent Loop'!$A$25=Inputs!$B$16,Inputs!$B$19,"")) | D25: =IF(B25="","",SUM($B$17:B25))
A26: 10 | B26: =IF('Agent Loop'!$A$26<=Inputs!$B$16,'Agent Loop'!$B$5+'Agent Loop'!$B$6+('Agent Loop'!$A$26-1)*'Agent Loop'!$B$7,"") | C26: =IF('Agent Loop'!$A$26<Inputs!$B$16,Inputs!$B$17,IF('Agent Loop'!$A$26=Inputs!$B$16,Inputs!$B$19,"")) | D26: =IF(B26="","",SUM($B$17:B26))
A27: Shows up to 10 steps. If you raise the step count above that, the totals stay correct.
A29: Cost per task by model
A30: Model | B30: Uncached input cost | C30: Cached input cost | D30: Output cost | E30: LLM cost per task (incl. retries) | F30: Monthly LLM cost
A31: =Inputs!$A$25 -> openai/gpt-oss-120b (Groq) | B31: ='Agent Loop'!$B$11*Inputs!$B$25*Inputs!$E$25/1000000 -> 0.0006696 | C31: ='Agent Loop'!$B$10*Inputs!$C$25*Inputs!$E$25/1000000 -> 0 | D31: ='Agent Loop'!$B$12*Inputs!$D$25*Inputs!$E$25/1000000 -> 0.000921 | E31: =('Agent Loop'!$B$31+'Agent Loop'!$C$31+'Agent Loop'!$D$31)*(1+Inputs!$B$20) -> 0.00174966 | F31: ='Agent Loop'!$E$31*Inputs!$B$9 -> 3.849252 | G31: =IF(Inputs!$A$25=Inputs!$B$29,"Selected","")
A32: =Inputs!$A$26 -> openai/gpt-oss-20b (Groq) | B32: ='Agent Loop'!$B$11*Inputs!$B$26*Inputs!$E$26/1000000 -> 0.0003348 | C32: ='Agent Loop'!$B$10*Inputs!$C$26*Inputs!$E$26/1000000 -> 0 | D32: ='Agent Loop'!$B$12*Inputs!$D$26*Inputs!$E$26/1000000 -> 0.0004605 | E32: =('Agent Loop'!$B$32+'Agent Loop'!$C$32+'Agent Loop'!$D$32)*(1+Inputs!$B$20) -> 0.00087483 | F32: ='Agent Loop'!$E$32*Inputs!$B$9 -> 1.924626 | G32: =IF(Inputs!$A$26=Inputs!$B$29,"Selected","")
A33: =Inputs!$A$27 -> qwen/qwen3.8-27b (Groq, preview) | B33: ='Agent Loop'!$B$11*Inputs!$B$27*Inputs!$E$27/1000000 -> 0.0035712 | C33: ='Agent Loop'!$B$10*Inputs!$C$27*Inputs!$E$27/1000000 -> 0 | D33: ='Agent Loop'!$B$12*Inputs!$D$27*Inputs!$E$27/1000000 -> 0.00614 | E33: =('Agent Loop'!$B$33+'Agent Loop'!$C$33+'Agent Loop'!$D$33)*(1+Inputs!$B$20) -> 0.01068232 | F33: ='Agent Loop'!$E$33*Inputs!$B$9 -> 23.501104 | G33: =IF(Inputs!$A$27=Inputs!$B$29,"Selected","")
A34: =Inputs!$A$28 -> Claude Haiku 5.5 (Anthropic) | B34: ='Agent Loop'!$B$11*Inputs!$B$28*Inputs!$E$28/1000000 -> 0.00058032 | C34: ='Agent Loop'!$B$10*Inputs!$C$28*Inputs!$E$28/1000000 -> 0 | D34: ='Agent Loop'!$B$12*Inputs!$D$28*Inputs!$E$28/1000000 -> 0.00099775 | E34: =('Agent Loop'!$B$34+'Agent Loop'!$C$34+'Agent Loop'!$D$34)*(1+Inputs!$B$20) -> 0.001735877 | F34: ='Agent Loop'!$E$34*Inputs!$B$9 -> 3.8189294 | G34: =IF(Inputs!$A$28=Inputs!$B$29,"Selected","") -> Selected
A36: All-in cost per task (selected model)
A37: Capture model | B37: =Inputs!$B$29 -> Claude Haiku 5.5 (Anthropic)
A38: LLM cost per task | B38: =INDEX($E$31:$E$34,MATCH(Inputs!$B$29,$A$31:$A$34,0)) -> 0.001735877
A39: Guardrail cost per task | B39: =Inputs!$B$33*(Inputs!$B$34*INDEX(Inputs!$B$25:$B$28,MATCH(Inputs!$B$32,Inputs!$A$25:$A$28,0))+Inputs!$B$35*INDEX(Inputs!$D$25:$D$28,MATCH(Inputs!$B$32,Inputs!$A$25:$A$28,0)))/1000000 -> 0
A40: Paid tool / API cost per task | B40: =Inputs!$B$39*Inputs!$C$39 -> 0
A41: Total cost per task | B41: ='Agent Loop'!$B$38+'Agent Loop'!$B$39+'Agent Loop'!$B$40 -> 0.001735877
A42: Monthly AI run cost (capture + on-demand) | B42: ='Agent Loop'!$B$41*Inputs!$B$9+'Agent Loop'!$B$50 -> 4.3278312
A44: On-demand AI features: monthly cost by model
A45: Model | B45: Email drafts / month | C45: Questions / month | D45: Email draft cost | E45: Question cost | F45: Monthly on-demand cost (both on this model) | G45: Selected for
...

Sheet Ask AI (RAG)
A1: Ask AI (RAG): pipeline questions
A2: Retrieval-augmented answers: each question sends a snapshot line for every CRM deal plus full details for the deals it mentions. Retrieval is SQL + keyword match today (no embeddings), so the prompt grows with the CRM.
A4: Context built per question
A5: System prompt | B5: =Inputs!$B$68 -> 166
A6: Answer schema + chat-format overhead | B6: =Inputs!$B$69 -> 477
A7: Pipeline snapshot (deals x tokens per line) | B7: =IF(Inputs!$B$74=1,MIN(Inputs!$B$75,Inputs!$B$66),Inputs!$B$66)*Inputs!$B$67 -> 1960
A8: Retrieved deal details (top-K x tokens per deal) | B8: =Inputs!$B$72*Inputs!$B$73 -> 442
A9: Chat history | B9: =Inputs!$B$71 -> 190
A10: Question | B10: =Inputs!$B$70 -> 25
A11: Total input tokens per question | B11: =SUM(B5:B10) -> 3260
A12: Output tokens per question | B12: =Inputs!$B$59 -> 600
A13: Snapshot share of the prompt | B13: =IF(B11=0,0,B7/B11) -> 0.60122699
A15: Cost per question by model
A16: Model | B16: Input cost | C16: Output cost | D16: Cost per question (incl. retries) | E16: Monthly cost | F16: Selected
A17: =Inputs!$A$25 -> openai/gpt-oss-120b (Groq) | B17: =$B$11*Inputs!$B$25*Inputs!$E$25/1000000 -> 0.000489 | C17: =$B$12*Inputs!$D$25*Inputs!$E$25/1000000 -> 0.00036 | D17: =(B17+C17)*(1+Inputs!$B$20) -> 0.0009339 | E17: =D17*Inputs!$B$57*Inputs!$B$8 -> 0.308187 | F17: =IF(Inputs!$A$25=Inputs!$B$63,"Ask AI model","") -> Ask AI model
A18: =Inputs!$A$26 -> openai/gpt-oss-20b (Groq) | B18: =$B$11*Inputs!$B$26*Inputs!$E$26/1000000 -> 0.0002445 | C18: =$B$12*Inputs!$D$26*Inputs!$E$26/1000000 -> 0.00018 | D18: =(B18+C18)*(1+Inputs!$B$20) -> 0.00046695 | E18: =D18*Inputs!$B$57*Inputs!$B$8 -> 0.1540935 | F18: =IF(Inputs!$A$26=Inputs!$B$63,"Ask AI model","")
A19: =Inputs!$A$27 -> qwen/qwen3.8-27b (Groq, preview) | B19: =$B$11*Inputs!$B$27*Inputs!$E$27/1000000 -> 0.002608 | C19: =$B$12*Inputs!$D$27*Inputs!$E$27/1000000 -> 0.0024 | D19: =(B19+C19)*(1+Inputs!$B$20) -> 0.0055088 | E19: =D19*Inputs!$B$57*Inputs!$B$8 -> 1.817904 | F19: =IF(Inputs!$A$27=Inputs!$B$63,"Ask AI model","")
A20: =Inputs!$A$28 -> Claude Haiku 5.5 (Anthropic) | B20: =$B$11*Inputs!$B$28*Inputs!$E$28/1000000 -> 0.0004238 | C20: =$B$12*Inputs!$D$28*Inputs!$E$28/1000000 -> 0.00039 | D20: =(B20+C20)*(1+Inputs!$B$20) -> 0.00089518 | E20: =D20*Inputs!$B$57*Inputs!$B$8 -> 0.2954094 | F20: =IF(Inputs!$A$28=Inputs!$B$63,"Ask AI model","")
A21: Questions per month | B21: =Inputs!$B$57*Inputs!$B$8 -> 330
A22: Monthly Ask AI cost (selected model) | B22: =INDEX($E$17:$E$20,MATCH(Inputs!$B$63,$A$17:$A$20,0)) -> 0.308187
A24: Embeddings (vector retrieval option)
A25: Vector retrieval on (1) or off (0) | B25: =Inputs!$B$74 -> 0
A26: One-time backfill tokens (every deal: line + details) | B26: =Inputs!$B$66*(Inputs!$B$67+Inputs!$B$73) -> 19640
A27: One-time backfill cost | B27: =B26*Inputs!$B$79/1000000 -> 0.0003928
A28: Monthly tokens embedded (new conversations + questions) | B28: =Inputs!$B$9*Inputs!$B$80+$B$21*Inputs!$B$70 -> 1152250
A29: Monthly embedding cost if switched on | B29: =B28*Inputs!$B$79/1000000 -> 0.023045 | C29: Inside Voyage's 200M free tokens for years at this volume
A30: Monthly embedding cost counted | B30: =B29*B25 -> 0
A32: Scaling: Ask AI cost as the CRM grows (selected Ask AI model)
A33: Deals in CRM | B33: Tokens / question, full snapshot (as built) | C33: Monthly cost, full snapshot | D33: Tokens / question, vector top-N | E33: Monthly cost, vector top-N + embeddings
A34: 40 | B34: =($B$5+$B$6+$B$8+$B$9+$B$10)+A34*Inputs!$B$67 -> 3260 | C34: =(B34*INDEX(Inputs!$B$25:$B$28,MATCH(Inputs!$B$63,Inputs!$A$25:$A$28,0))+$B$12*INDEX(Inputs!$D$25:$D$28,MATCH(Inputs!$B$63,Inputs!$A$25:$A$28,0)))*INDEX(Inputs!$E$25:$E$28,MATCH(Inputs!$B$63,Inputs!$A$25:$A$28,0))/1000000*(1+Inputs!$B$20)*$B$21 -> 0.308187 | D34: =($B$5+$B$6+$B$8+$B$9+$B$10)+MIN(Inputs!$B$75,A34)*Inputs!$B$67 -> 2280 | E34: =(D34*INDEX(Inputs!$B$25:$B$28,MATCH(Inputs!$B$63,Inputs!$A$25:$A$28,0))+$B$12*INDEX(Inputs!$D$25:$D$28,MATCH(Inputs!$B$63,Inputs!$A$25:$A$28,0)))*INDEX(Inputs!$E$25:$E$28,MATCH(Inputs!$B$63,Inputs!$A$25:$A$28,0))/1000000*(1+Inputs!$B$20)*$B$21+$B$29 -> 0.277871
A35: 100 | B35: =($B$5+$B$6+$B$8+$B$9+$B$10)+A35*Inputs!$B$67 -> 6200 | C35: =(B35*INDEX(Inputs!$B$25:$B$28,MATCH(Inputs!$B$63,Inputs!$A$25:$A$28,0))+$B$12*INDEX(Inputs!$D$25:$D$28,MATCH(Inputs!$B$63,Inputs!$A$25:$A$28,0)))*INDEX(Inputs!$E$25:$E$28,MATCH(Inputs!$B$63,Inputs!$A$25:$A$28,0))/1000000*(1+Inputs!$B$20)*$B$21 -> 0.46827 | D35: =($B$5+$B$6+$B$8+$B$9+$B$10)+MIN(Inputs!$B$75,A35)*Inputs!$B$67 -> 2280 | E35: =(D35*INDEX(Inputs!$B$25:$B$28,MATCH(Inputs!$B$63,Inputs!$A$25:$A$28,0))+$B$12*INDEX(Inputs!$D$25:$D$28,MATCH(Inputs!$B$63,Inputs!$A$25:$A$28,0)))*INDEX(Inputs!$E$25:$E$28,MATCH(Inputs!$B$63,Inputs!$A$25:$A$28,0))/1000000*(1+Inputs!$B$20)*$B$21+$B$29 -> 0.277871
A36: 250 | B36: =($B$5+$B$6+$B$8+$B$9+$B$10)+A36*Inputs!$B$67 -> 13550 | C36: =(B36*INDEX(Inputs!$B$25:$B$28,MATCH(Inputs!$B$63,Inputs!$A$25:$A$28,0))+$B$12*INDEX(Inputs!$D$25:$D$28,MATCH(Inputs!$B$63,Inputs!$A$25:$A$28,0)))*INDEX(Inputs!$E$25:$E$28,MATCH(Inputs!$B$63,Inputs!$A$25:$A$28,0))/1000000*(1+Inputs!$B$20)*$B$21 -> 0.8684775 | D36: =($B$5+$B$6+$B$8+$B$9+$B$10)+MIN(Inputs!$B$75,A36)*Inputs!$B$67 -> 2280 | E36: =(D36*INDEX(Inputs!$B$25:$B$28,MATCH(Inputs!$B$63,Inputs!$A$25:$A$28,0))+$B$12*INDEX(Inputs!$D$25:$D$28,MATCH(Inputs!$B$63,Inputs!$A$25:$A$28,0)))*INDEX(Inputs!$E$25:$E$28,MATCH(Inputs!$B$63,Inputs!$A$25:$A$28,0))/1000000*(1+Inputs!$B$20)*$B$21+$B$29 -> 0.277871
A37: 500 | B37: =($B$5+$B$6+$B$8+$B$9+$B$10)+A37*Inputs!$B$67 -> 25800 | C37: =(B37*INDEX(Inputs!$B$25:$B$28,MATCH(Inputs!$B$63,Inputs!$A$25:$A$28,0))+$B$12*INDEX(Inputs!$D$25:$D$28,MATCH(Inputs!$B$63,Inputs!$A$25:$A$28,0)))*INDEX(Inputs!$E$25:$E$28,MATCH(Inputs!$B$63,Inputs!$A$25:$A$28,0))/1000000*(1+Inputs!$B$20)*$B$21 -> 1.53549 | D37: =($B$5+$B$6+$B$8+$B$9+$B$10)+MIN(Inputs!$B$75,A37)*Inputs!$B$67 -> 2280 | E37: =(D37*INDEX(Inputs!$B$25:$B$28,MATCH(Inputs!$B$63,Inputs!$A$25:$A$28,0))+$B$12*INDEX(Inputs!$D$25:$D$28,MATCH(Inputs!$B$63,Inputs!$A$25:$A$28,0)))*INDEX(Inputs!$E$25:$E$28,MATCH(Inputs!$B$63,Inputs!$A$25:$A$28,0))/1000000*(1+Inputs!$B$20)*$B$21+$B$29 -> 0.277871
A38: 1000 | B38: =($B$5+$B$6+$B$8+$B$9+$B$10)+A38*Inputs!$B$67 -> 50300 | C38: =(B38*INDEX(Inputs!$B$25:$B$28,MATCH(Inputs!$B$63,Inputs!$A$25:$A$28,0))+$B$12*INDEX(Inputs!$D$25:$D$28,MATCH(Inputs!$B$63,Inputs!$A$25:$A$28,0)))*INDEX(Inputs!$E$25:$E$28,MATCH(Inputs!$B$63,Inputs!$A$25:$A$28,0))/1000000*(1+Inputs!$B$20)*$B$21 -> 2.869515 | D38: =($B$5+$B$6+$B$8+$B$9+$B$10)+MIN(Inputs!$B$75,A38)*Inputs!$B$67 -> 2280 | E38: =(D38*INDEX(Inputs!$B$25:$B$28,MATCH(Inputs!$B$63,Inputs!$A$25:$A$28,0))+$B$12*INDEX(Inputs!$D$25:$D$28,MATCH(Inputs!$B$63,Inputs!$A$25:$A$28,0)))*INDEX(Inputs!$E$25:$E$28,MATCH(Inputs!$B$63,Inputs!$A$25:$A$28,0))/1000000*(1+Inputs!$B$20)*$B$21+$B$29 -> 0.277871
A39: 2000 | B39: =($B$5+$B$6+$B$8+$B$9+$B$10)+A39*Inputs!$B$67 -> 99300 | C39: =(B39*INDEX(Inputs!$B$25:$B$28,MATCH(Inputs!$B$63,Inputs!$A$25:$A$28,0))+$B$12*INDEX(Inputs!$D$25:$D$28,MATCH(Inputs!$B$63,Inputs!$A$25:$A$28,0)))*INDEX(Inputs!$E$25:$E$28,MATCH(Inputs!$B$63,Inputs!$A$25:$A$28,0))/1000000*(1+Inputs!$B$20)*$B$21 -> 5.537565 | D39: =($B$5+$B$6+$B$8+$B$9+$B$10)+MIN(Inputs!$B$75,A39)*Inputs!$B$67 -> 2280 | E39: =(D39*INDEX(Inputs!$B$25:$B$28,MATCH(Inputs!$B$63,Inputs!$A$25:$A$28,0))+$B$12*INDEX(Inputs!$D$25:$D$28,MATCH(Inputs!$B$63,Inputs!$A$25:$A$28,0)))*INDEX(Inputs!$E$25:$E$28,MATCH(Inputs!$B$63,Inputs!$A$25:$A$28,0))/1000000*(1+Inputs!$B$20)*$B$21+$B$29 -> 0.277871
A40: Full snapshot is simplest and fine at today's size. Past a few hundred deals the prompt passes 10-25K tokens per question: slower answers, and the model has more to read past. Switch to vector top-N then.

Sheet Cost Saving
A1: Cost Saving
A2: Human team today vs the AI agent with human escalation
A4: Human agents today
A5: Monthly task volume | B5: =Inputs!$B$9 -> 2200
A6: Tasks handled per agent per month | B6: =Inputs!$B$48*Inputs!$B$8 -> 2112
A7: Human agents required (FTE) | B7: =Inputs!$B$9/'Cost Saving'!$B$6 -> 1.0416667 | C7: Fractional FTE; round up when hiring
A8: Cost per agent per month | B8: =Inputs!$B$49+Inputs!$B$50 -> 4000
A9: Total monthly cost of human agents | B9: ='Cost Saving'!$B$7*'Cost Saving'!$B$8 -> 4166.6667
A11: AI agent
A12: Agent run cost (LLM + guardrails + tools) | B12: ='Agent Loop'!$B$42 -> 4.3278312
A13: Embeddings | B13: ='Ask AI (RAG)'!$B$30 -> 0 | C13: Ask AI vector retrieval (0 while retrieval mode = full snapshot)
A14: One-time embedding backfill | B14: ='Ask AI (RAG)'!$B$27*Inputs!$B$74 -> 0
A15: Infrastructure | B15: =Inputs!$B$42 -> 0
A16: Human agents still needed (escalations) | B16: ='Cost Saving'!$B$9*(1-Inputs!$B$51) -> 1250 | C16: Human cost x (1 - automation rate)
A17: Total monthly cost with the AI agent | B17: ='Agent Loop'!$B$42+'Cost Saving'!$B$13+'Cost Saving'!$B$15+'Cost Saving'!$B$16 -> 1254.3278
A19: Saving
A20: Monthly saving | B20: ='Cost Saving'!$B$9-'Cost Saving'!$B$17 -> 2912.3388
A21: % saving | B21: =IF('Cost Saving'!$B$9=0,0,'Cost Saving'!$B$20/'Cost Saving'!$B$9) -> 0.69896132
A22: Annual saving | B22: ='Cost Saving'!$B$20*12 -> 34948.066
A23: One-time costs | B23: ='Cost Saving'!$B$14+Inputs!$B$45 -> 0
A24: Payback period (months) | B24: =IF('Cost Saving'!$B$20<=0,"No payback",'Cost Saving'!$B$23/'Cost Saving'!$B$20) -> 0
A25: Break-even cost per task (saving = 0) | B25: =('Cost Saving'!$B$9-'Cost Saving'!$B$13-'Cost Saving'!$B$15-'Cost Saving'!$B$16)/Inputs!$B$9 -> 1.3257576 | C25: The agent stops saving money above this all-in cost per task

Sheet Assumptions
A1: Assumptions and notes
A4: • Scope: LLM cost only for the prototype as deployed on 11 Oct 2026 (Railway). Hosting, infrastructure, development and go-live costs are excluded by request.
A5: • Prices (per 1M tokens): Claude Haiku 5.5 $0.10 in / $0.01 cache hit / $0.50 out for prompts up to 100K tokens (platform.claude.com/docs/en/about-claude/pricing, checked 11 Oct 2026); openai/gpt-oss-120b $0.15 / $0.60 and openai/gpt-oss-20b $0.075 / $0.30, qwen/qwen3.8-27b $0.80 / $4.00 (console.groq.com/docs/models, checked 7 Oct 2026); voyage-4-lite embeddings $0.02 with the first 200M tokens free (docs.voyageai.com/docs/pricing, checked 11 Oct 2026).
A6: • A 'task' is one captured sales conversation (email thread, meeting note or shared LinkedIn chat): 100 per working day across the 4 sellers, 22 working days a month (user's choice).
A7: • Three LLM calls per captured conversation: (1) classify (new lead, existing deal, existing client, internal note about several deals, not sales), (2) extract CRM fields, summary, follow-ups and new needs, (3) date check for revisit dates and deferrals. CRM matching, masking, grounding and reminder rules are code.
A8: • Measured live on 9 Oct 2026 (openai/gpt-oss-120b on Groq, 4 sample conversations): classify ~690 in / ~105 out, extract ~2,780 in / ~1,105 out, date check ~836 in / ~250 out tokens. The workbook spreads this as 3 calls x 1,488 input tokens (690 prompt + 278 schema + 520 conversation).
A9: • Cross-sell (existing clients, ~25% of conversations, ~630 in / ~300 out) is folded into the final-call output. Internal notes about several deals (~5%) run one split call (~860 in) instead of extract + date check, so they cost less and are not modelled separately.
A10: • On-demand features: follow-up email drafts (~940 in / ~450 out, Claude Haiku 5.5) and Ask AI pipeline questions (RAG, Groq gpt-oss-120b; built on the Ask AI (RAG) sheet). Input sizes are the app's real prompts counted with the o200k tokenizer; output sizes are assumptions.
A11: • Retry rate 10% (rate-limit retries and a single warmer retry when the provider rejects malformed JSON).
A12: • Prompt caching is not counted (0% cache hits), which is conservative. Groq caches gpt-oss prompts automatically at 50% off; Claude needs explicit cache markers and a longer prefix than this app sends, and charges 1.25x for cache writes.
A13: • Token counts were measured with the o200k tokenizer (gpt-oss). Claude Haiku 5.5's tokenizer counts the same text as about 30% more tokens, applied through the tokenizer factor (Inputs column E). Reasoning length at effort low is assumed equal to gpt-oss.
A14: • No LLM guardrail call: masking, the evidence check against the source and exclusion rules are code, and the owner confirms every draft.
... A25: • Capture on Claude Haiku 5.5 is billed at the up-to-100K-token price: a capture call is ~1,500 tokens and an Ask AI call stays far below 100K until roughly 2,000 deals.
